python: can't open file '/home/quicksilver/Documents/crisis-curation/crisisServer.py': [Errno 2] No such file or directory
python: can't open file '/home/quicksilver/Documents/crisis-curation/historicalTweets.py': [Errno 2] No such file or directory
Traceback (most recent call last):
  File ".//crisisServer.py", line 289, in <module>
    dbclient =  MongoClient('localhost', 27017)
  File "/usr/local/lib/python2.7/dist-packages/pymongo/mongo_client.py", line 352, in __init__
    raise ConnectionFailure(str(e))
pymongo.errors.ConnectionFailure: could not connect to localhost:27017: [Errno 111] Connection refused
Traceback (most recent call last):
  File ".//historicalTweets.py", line 23, in <module>
    dbclient = MongoClient('localhost', 27017)
  File "/usr/local/lib/python2.7/dist-packages/pymongo/mongo_client.py", line 352, in __init__
    raise ConnectionFailure(str(e))
pymongo.errors.ConnectionFailure: could not connect to localhost:27017: [Errno 111] Connection refused
Traceback (most recent call last):
  File ".//crisisServer.py", line 289, in <module>
    dbclient =  MongoClient('localhost', 27017)
  File "/usr/local/lib/python2.7/dist-packages/pymongo/mongo_client.py", line 352, in __init__
    raise ConnectionFailure(str(e))
pymongo.errors.ConnectionFailure: could not connect to localhost:27017: [Errno 111] Connection refused
Traceback (most recent call last):
  File ".//historicalTweets.py", line 23, in <module>
    dbclient = MongoClient('localhost', 27017)
  File "/usr/local/lib/python2.7/dist-packages/pymongo/mongo_client.py", line 352, in __init__
    raise ConnectionFailure(str(e))
pymongo.errors.ConnectionFailure: could not connect to localhost:27017: [Errno 111] Connection refused
